Workbook

Sheet Sheet 1
A1: Adjustment | B1: 1 | C1: Other
A2: Afternoon with the baker | B2: 40 | C2: Other
A3: Alfajores | B3: =VLOOKUP(A3,Sheet1!$A$2:$B$96,2,FALSE) -> 3.5 | C3: Food
A4: Argentina Night | B4: 30 | C4: Other
A5: Art Tray | B5: =VLOOKUP(A5,Sheet1!$A$2:$B$96,2,FALSE) -> 15 | C5: Other
A6: Bacon | B6: =VLOOKUP(A6,Sheet1!$A$2:$B$96,2,FALSE) -> 2 | C6: Food
A7: Baguette | B7: =VLOOKUP(A7,Sheet1!$A$2:$B$96,2,FALSE) -> 4 | C7: Food
A8: Bakewell | B8: =VLOOKUP(A8,Sheet1!$A$2:$B$96,2,FALSE) -> 4.5 | C8: Food
A9: Bare Popcorn | B9: =VLOOKUP(A9,Sheet1!$A$2:$B$96,2,FALSE) -> 2 | C9: Food
A10: Basket | B10: =VLOOKUP(A10,Sheet1!$A$2:$B$96,2,FALSE) -> 12 | C10: Food
A11: Bowl Nic Pitt | B11: =VLOOKUP(A11,Sheet1!$A$2:$B$96,2,FALSE) -> 6 | C11: Food
A12: Bread | B12: =VLOOKUP(A12,Sheet1!$A$2:$B$96,2,FALSE) -> 5 | C12: Food
A13: Bread Pudding | B13: =VLOOKUP(A13,Sheet1!$A$2:$B$96,2,FALSE) -> 4.5 | C13: Food
A14: Brioche and salami | B14: 10 | C14: Food
A15: Brownie | B15: =VLOOKUP(A15,Sheet1!$A$2:$B$96,2,FALSE) -> 3 | C15: Food
A16: Cake | B16: 7 | C16: Food
A17: Caramel bites | B17: =VLOOKUP(A17,Sheet1!$A$2:$B$96,2,FALSE) -> 3 | C17: Food
A18: Cherry me Dried fruit | B18: =VLOOKUP(A18,Sheet1!$A$2:$B$96,2,FALSE) -> 3.5 | C18: Food
A19: Chicken sand | B19: =VLOOKUP(A19,Sheet1!$A$2:$B$96,2,FALSE) -> 7 | C19: Food
A20: Chicken Stew | B20: =VLOOKUP(A20,Sheet1!$A$2:$B$96,2,FALSE) -> 8 | C20: Food
A21: Chimichurri Oil | B21: =VLOOKUP(A21,Sheet1!$A$2:$B$96,2,FALSE) -> 4 | C21: Food
A22: Chocolates | B22: =VLOOKUP(A22,Sheet1!$A$2:$B$96,2,FALSE) -> 2 | C22: Food
A23: Christmas common | B23: =VLOOKUP(A23,Sheet1!$A$2:$B$96,2,FALSE) -> 5 | C23: Food
A24: Coffee | B24: =VLOOKUP(A24,Sheet1!$A$2:$B$96,2,FALSE) -> 3 | C24: Beverage
A25: Coffee granules | B25: =VLOOKUP(A25,Sheet1!$A$2:$B$96,2,FALSE) -> 7 | C25: Other
A26: Coke | B26: =VLOOKUP(A26,Sheet1!$A$2:$B$96,2,FALSE) -> 2 | C26: Beverage
A27: Cookies | B27: 4 | C27: Food
A28: Crepes | B28: =VLOOKUP(A28,Sheet1!$A$2:$B$96,2,FALSE) -> 7 | C28: Food
A29: Crisps | B29: =VLOOKUP(A29,Sheet1!$A$2:$B$96,2,FALSE) -> 2 | C29: Food
A30: Drinking chocolate spoons | B30: =VLOOKUP(A30,Sheet1!$A$2:$B$96,2,FALSE) -> 4 | C30: Food
A31: Duck egg | B31: =VLOOKUP(A31,Sheet1!$A$2:$B$96,2,FALSE) -> 3 | C31: Food
A32: Dulce de Leche | B32: =VLOOKUP(A32,Sheet1!$A$2:$B$96,2,FALSE) -> 4 | C32: Food
A33: Eggs | B33: =VLOOKUP(A33,Sheet1!$A$2:$B$96,2,FALSE) -> 2 | C33: Food
A34: Ella's Kitchen Pouches | B34: =VLOOKUP(A34,Sheet1!$A$2:$B$96,2,FALSE) -> 3.5 | C34: Food
A35: Empanadas | B35: =VLOOKUP(A35,Sheet1!$A$2:$B$96,2,FALSE) -> 3.5 | C35: Food
A36: Extra Salami or Feta | B36: =VLOOKUP(A36,Sheet1!$A$2:$B$96,2,FALSE) -> 2 | C36: Food
A37: Fairy Doors | B37: =VLOOKUP(A37,Sheet1!$A$2:$B$96,2,FALSE) -> 4 | C37: Food
A38: Farm House | B38: =VLOOKUP(A38,Sheet1!$A$2:$B$96,2,FALSE) -> 12 | C38: Food
A39: Focaccia | B39: =VLOOKUP(A39,Sheet1!$A$2:$B$96,2,FALSE) -> 4.5 | C39: Food
... A93: Vegan mincepie | B93: =VLOOKUP(A93,Sheet1!$A$2:$B$96,2,FALSE) -> 3.5 | C93: Food
...

Sheet Sheet1
A1: Item | B1: Price
A2: Alfajores | B2: 3.5
A3: Argentina Night (specialty) | B3: 6
A4: Art Tray | B4: 15
A5: Bacon | B5: 2
A6: Baguette | B6: 4
A7: Bakewell | B7: 4.5
A8: Bare Popcorn | B8: 2
A9: Basket | B9: 12
A10: Bowl Nic Pitt | B10: 6
A11: Bread | B11: 5
A12: Bread Pudding | B12: 4.5
A13: Brioche & salami | B13: 5.5
... A96: Victorian Sponge (whole) | B96: 28
